Workbook
Name solver_eng: 0
Name solver_eng: 0
Name solver_eng: 0
Name solver_eng: 0
Name solver_eng: 0
Name solver_eng: 0
Name solver_eng: 0
Name solver_eng: 0
Name solver_eng: 0
Name solver_eng: 0
Name solver_eng: 0
Name solver_eng: 0
Name solver_eng: 0
Name solver_eng: 0
Name solver_eng: 0
Name solver_eng: 0
Name solver_eng: 0
Name solver_eng: 0
Name solver_eng: 0
Name solver_eng: 0
Name solver_eng: 0
Name solver_eng: 0
Name solver_eng: 0
Name solver_eng: 0

Sheet ScenarioParameters
A1: Scenario input parameters | D1: Data imported from Winter's method | E1: Year | F1: Quarter | G1: =IFERROR(__xludf.DUMMYFUNCTION("IMPORTRANGE(""https://docs.google.com/spreadsheets/d/1Y3ibnN86RzRcOvz_3iryQpOSIamHQku_1S-6YqExw5w/edit?gid=1531545304#gid=1531545304"", ""Winter!H1:H18"")"),"Forecast") -> Forecast
A2: Sales & Product Volume (units/year) | B2: Values imported from forecast
A3: Development Cost (total $) | B3: 60480 | E3: 1 | F3: 1 | G3: =IFERROR(__xludf.DUMMYFUNCTION("""COMPUTED_VALUE"""),3106.96607) -> 3106.9661
A4: Unit price ($/unit) | B4: 299 | E4: 1 | F4: 2 | G4: =IFERROR(__xludf.DUMMYFUNCTION("""COMPUTED_VALUE"""),7938.07622732285) -> 7938.0762
A5: Unit Productions Cost ($/unit) | B5: 115.28 | E5: 1 | F5: 3 | G5: =IFERROR(__xludf.DUMMYFUNCTION("""COMPUTED_VALUE"""),6160.35736753071) -> 6160.3574
A6: Ramp-up cost (total S) | B6: 6048 | E6: 1 | F6: 4 | G6: =IFERROR(__xludf.DUMMYFUNCTION("""COMPUTED_VALUE"""),11872.917093341) -> 11872.917
A7: Marketing & suppost cost ($/year) | B7: 840000 | E7: 2 | F7: 1 | G7: =IFERROR(__xludf.DUMMYFUNCTION("""COMPUTED_VALUE"""),6518.25608721043) -> 6518.2561
A8: Annual Discount Factor (%) | B8: 7 | E8: 2 | F8: 2 | G8: =IFERROR(__xludf.DUMMYFUNCTION("""COMPUTED_VALUE"""),12977.6452429524) -> 12977.645
E9: 2 | F9: 3 | G9: =IFERROR(__xludf.DUMMYFUNCTION("""COMPUTED_VALUE"""),8761.31976315513) -> 8761.3198
E10: 2 | F10: 4 | G10: =IFERROR(__xludf.DUMMYFUNCTION("""COMPUTED_VALUE"""),15586.1371602808) -> 15586.137
E11: 3 | F11: 1 | G11: =IFERROR(__xludf.DUMMYFUNCTION("""COMPUTED_VALUE"""),8260.82892471973) -> 8260.8289
E12: 3 | F12: 2 | G12: =IFERROR(__xludf.DUMMYFUNCTION("""COMPUTED_VALUE"""),16215.6619147742) -> 16215.662
E13: 3 | F13: 3 | G13: =IFERROR(__xludf.DUMMYFUNCTION("""COMPUTED_VALUE"""),10767.2672275139) -> 10767.267
E14: 3 | F14: 4 | G14: =IFERROR(__xludf.DUMMYFUNCTION("""COMPUTED_VALUE"""),18944.3198782037) -> 18944.32
E15: 4 | F15: 1 | G15: =IFERROR(__xludf.DUMMYFUNCTION("""COMPUTED_VALUE"""),10119.1388926823) -> 10119.139
E16: 4 | F16: 2 | G16: =IFERROR(__xludf.DUMMYFUNCTION("""COMPUTED_VALUE"""),19669.2232429464) -> 19669.223
E17: 4 | F17: 3 | G17: =IFERROR(__xludf.DUMMYFUNCTION("""COMPUTED_VALUE"""),12944.5202254938) -> 12944.52
E18: 4 | F18: 4 | G18: =IFERROR(__xludf.DUMMYFUNCTION("""COMPUTED_VALUE"""),22590.7225478699) -> 22590.723

Sheet BaseCase
A1: BaseCase
B2: Year 0, Development | F2: Year 1, Projection | J2: Year 2, Projection | N2: Year 3, Projection | R2: Year 4, Projection
A3: Period | B3: 1 | C3: =B3+1 -> 2 | D3: =C3+1 -> 3 | E3: =D3+1 -> 4 | F3: =E3+1 -> 5 | G3: =F3+1 -> 6 | H3: =G3+1 -> 7 | I3: =H3+1 -> 8 | J3: =I3+1 -> 9 | ... U3: =T3+1 -> 20
A4: ($Value in thousands) | B4: Q1 | C4: Q2 | D4: Q3 | E4: Q4 | F4: Q1 | G4: Q2 | H4: Q3 | I4: Q4 | J4: Q1 | K4: Q2 | L4: Q3 | M4: Q4 | N4: Q1 | O4: Q2 | P4: Q3 | Q4: Q4 | R4: Q1 | S4: Q2 | T4: Q3 | U4: Q4
A6: Development Cost | B6: =(-1)*ScenarioParameters!$B$3/4*(1/1000) -> -15.12 | C6: =(-1)*ScenarioParameters!$B$3/4*(1/1000) -> -15.12 | D6: =(-1)*ScenarioParameters!$B$3/4*(1/1000) -> -15.12 | E6: =(-1)*ScenarioParameters!$B$3/4*(1/1000) -> -15.12
A7: Ramp-up cost | E7: =(-1)*ScenarioParameters!$B$6/2*(1/1000) -> -3.024 | F7: =(-1)*ScenarioParameters!$B$6/2*(1/1000) -> -3.024
A8: Marketing & support cost | F8: =(-1)*ScenarioParameters!$B$7/4*(1/1000) -> -210 | G8: =(-1)*ScenarioParameters!$B$7/4*(1/1000) -> -210 | H8: =(-1)*ScenarioParameters!$B$7/4*(1/1000) -> -210 | I8: =(-1)*ScenarioParameters!$B$7/4*(1/1000) -> -210 | J8: =(-1)*ScenarioParameters!$B$7/4*(1/1000) -> -210 | K8: =(-1)*ScenarioParameters!$B$7/4*(1/1000) -> -210 | L8: =(-1)*ScenarioParameters!$B$7/4*(1/1000) -> -210 | M8: =(-1)*ScenarioParameters!$B$7/4*(1/1000) -> -210 | ... U8: =(-1)*ScenarioParameters!$B$7/4*(1/1000) -> -210
A9: Production Cost | F9: =(-1)*(ScenarioParameters!$B$5)*ScenarioParameters!$G3*(1/1000) -> -358.17105 | G9: =(-1)*(ScenarioParameters!$B$5)*ScenarioParameters!$G4*(1/1000) -> -915.10143 | H9: =(-1)*(ScenarioParameters!$B$5)*ScenarioParameters!$G5*(1/1000) -> -710.166 | I9: =(-1)*(ScenarioParameters!$B$5)*ScenarioParameters!$G6*(1/1000) -> -1368.7099 | J9: =(-1)*(ScenarioParameters!$B$5)*ScenarioParameters!$G7*(1/1000) -> -751.42456 | K9: =(-1)*(ScenarioParameters!$B$5)*ScenarioParameters!$G8*(1/1000) -> -1496.0629 | L9: =(-1)*(ScenarioParameters!$B$5)*ScenarioParameters!$G9*(1/1000) -> -1010.0049 | M9: =(-1)*(ScenarioParameters!$B$5)*ScenarioParameters!$G10*(1/1000) -> -1796.7699 | N9: =(-1)*(ScenarioParameters!$B$5)*ScenarioParameters!$G11*(1/1000) -> -952.30836 | O9: =(-1)*(ScenarioParameters!$B$5)*ScenarioParameters!$G12*(1/1000) -> -1869.3415 | P9: =(-1)*(ScenarioParameters!$B$5)*ScenarioParameters!$G13*(1/1000) -> -1241.2506 | Q9: =(-1)*(ScenarioParameters!$B$5)*ScenarioParameters!$G14*(1/1000) -> -2183.9012 | R9: =(-1)*(ScenarioParameters!$B$5)*ScenarioParameters!$G15*(1/1000) -> -1166.5343 | S9: =(-1)*(ScenarioParameters!$B$5)*ScenarioParameters!$G16*(1/1000) -> -2267.4681 | T9: =(-1)*(ScenarioParameters!$B$5)*ScenarioParameters!$G17*(1/1000) -> -1492.2443 | U9: =(-1)*(ScenarioParameters!$B$5)*ScenarioParameters!$G18*(1/1000) -> -2604.2585
A10: Production volume | F10: =ScenarioParameters!$G3 -> 3106.9661 | G10: =ScenarioParameters!$G4 -> 7938.0762 | H10: =ScenarioParameters!$G5 -> 6160.3574 | I10: =ScenarioParameters!$G6 -> 11872.917 | J10: =ScenarioParameters!$G7 -> 6518.2561 | K10: =ScenarioParameters!$G8 -> 12977.645 | L10: =ScenarioParameters!$G9 -> 8761.3198 | M10: =ScenarioParameters!$G10 -> 15586.137 | N10: =ScenarioParameters!$G11 -> 8260.8289 | O10: =ScenarioParameters!$G12 -> 16215.662 | P10: =ScenarioParameters!$G13 -> 10767.267 | Q10: =ScenarioParameters!$G14 -> 18944.32 | R10: =ScenarioParameters!$G15 -> 10119.139 | S10: =ScenarioParameters!$G16 -> 19669.223 | T10: =ScenarioParameters!$G17 -> 12944.52 | U10: =ScenarioParameters!$G18 -> 22590.723
A11: Unit product cost | F11: =F9/F10 -> -0.11528 | G11: =G9/G10 -> -0.11528 | H11: =H9/H10 -> -0.11528 | I11: =I9/I10 -> -0.11528 | J11: =J9/J10 -> -0.11528 | K11: =K9/K10 -> -0.11528 | L11: =L9/L10 -> -0.11528 | M11: =M9/M10 -> -0.11528 | ... U11: =U9/U10 -> -0.11528
A12: Sales revenue | F12: =(ScenarioParameters!$B$4*F10)*(1/1000) -> 928.98285 | G12: =(ScenarioParameters!$B$4*G10)*(1/1000) -> 2373.4848 | H12: =(ScenarioParameters!$B$4*H10)*(1/1000) -> 1841.9469 | I12: =(ScenarioParameters!$B$4*I10)*(1/1000) -> 3550.0022 | J12: =(ScenarioParameters!$B$4*J10)*(1/1000) -> 1948.9586 | K12: =(ScenarioParameters!$B$4*K10)*(1/1000) -> 3880.3159 | L12: =(ScenarioParameters!$B$4*L10)*(1/1000) -> 2619.6346 | M12: =(ScenarioParameters!$B$4*M10)*(1/1000) -> 4660.255 | ... U12: =(ScenarioParameters!$B$4*U10)*(1/1000) -> 6754.626
A13: Forecasted Sales Volume | F13: =F$10 -> 3106.9661 | G13: =G$10 -> 7938.0762 | H13: =H$10 -> 6160.3574 | I13: =I$10 -> 11872.917 | J13: =J$10 -> 6518.2561 | K13: =K$10 -> 12977.645 | L13: =L$10 -> 8761.3198 | M13: =M$10 -> 15586.137 | ... U13: =U$10 -> 22590.723
A14: Unit price | F14: =F$12/F$13 -> 0.299 | G14: =G$12/G$13 -> 0.299 | H14: =H$12/H$13 -> 0.299 | I14: =I$12/I$13 -> 0.299 | J14: =J$12/J$13 -> 0.299 | K14: =K$12/K$13 -> 0.299 | L14: =L$12/L$13 -> 0.299 | M14: =M$12/M$13 -> 0.299 | ... U14: =U$12/U$13 -> 0.299
A16: Period Cash Flow | B16: =SUM(B6+B7+B8+B9+B12) -> -15.12 | C16: =SUM(C6+C7+C8+C9+C12) -> -15.12 | D16: =SUM(D6+D7+D8+D9+D12) -> -15.12 | E16: =SUM(E6+E7+E8+E9+E12) -> -18.144 | F16: =SUM(F6+F7+F8+F9+F12) -> 357.78781 | G16: =SUM(G6+G7+G8+G9+G12) -> 1248.3834 | H16: =SUM(H6+H7+H8+H9+H12) -> 921.78086 | I16: =SUM(I6+I7+I8+I9+I12) -> 1971.2923 | ... U16: =SUM(U6+U7+U8+U9+U12) -> 3940.3675
A17: Unit Price | B17: =B16 -> -15.12 | C17: =C16/(1+(ScenarioParameters!$B$8/100)/4)^B3 -> -14.859951 | D17: =D16/(1+(ScenarioParameters!$B$8/100)/4)^C3 -> -14.604374 | E17: =E16/(1+(ScenarioParameters!$B$8/100)/4)^D3 -> -17.223832 | F17: =F16/(1+(ScenarioParameters!$B$8/100)/4)^E3 -> 333.80118 | G17: =G16/(1+(ScenarioParameters!$B$8/100)/4)^F3 -> 1144.6584 | H17: =H16/(1+(ScenarioParameters!$B$8/100)/4)^G3 -> 830.65594 | I17: =I16/(1+(ScenarioParameters!$B$8/100)/4)^H3 -> 1745.8628 | J17: =J16/(1+(ScenarioParameters!$B$8/100)/4)^I3 -> 859.56103 | ... U17: =U16/(1+(ScenarioParameters!$B$8/100)/4)^T3 -> 2833.8887
A19: Project NVP | B19: =SUM(B17:U17) -> 25465.99
A21: Forecasted Sales Volume from Winter's forecasting method*

Sheet +10 UnitCost
A1: Unit Cost Analysis: | B1: 0.1
B2: Year 0, Development | F2: Year 1, Projection | J2: Year 2, Projection | N2: Year 3, Projection | R2: Year 4, Projection
A3: Period | B3: 1 | C3: =B3+1 -> 2 | D3: =C3+1 -> 3 | E3: =D3+1 -> 4 | F3: =E3+1 -> 5 | G3: =F3+1 -> 6 | H3: =G3+1 -> 7 | I3: =H3+1 -> 8 | J3: =I3+1 -> 9 | ... U3: =T3+1 -> 20
A4: ($Value in thousands) | B4: Q1 | C4: Q2 | D4: Q3 | E4: Q4 | F4: Q1 | G4: Q2 | H4: Q3 | I4: Q4 | J4: Q1 | K4: Q2 | L4: Q3 | M4: Q4 | N4: Q1 | O4: Q2 | P4: Q3 | Q4: Q4 | R4: Q1 | S4: Q2 | T4: Q3 | U4: Q4
A6: Development Cost | B6: =(-1)*ScenarioParameters!$B$3/4*(1/1000) -> -15.12 | C6: =(-1)*ScenarioParameters!$B$3/4*(1/1000) -> -15.12 | D6: =(-1)*ScenarioParameters!$B$3/4*(1/1000) -> -15.12 | E6: =(-1)*ScenarioParameters!$B$3/4*(1/1000) -> -15.12
A7: Ramp-up cost | E7: =(-1)*ScenarioParameters!$B$6/2*(1/1000) -> -3.024 | F7: =(-1)*ScenarioParameters!$B$6/2*(1/1000) -> -3.024
A8: Marketing & support cost | F8: =(-1)*ScenarioParameters!$B$7/4*(1/1000) -> -210 | G8: =(-1)*ScenarioParameters!$B$7/4*(1/1000) -> -210 | H8: =(-1)*ScenarioParameters!$B$7/4*(1/1000) -> -210 | I8: =(-1)*ScenarioParameters!$B$7/4*(1/1000) -> -210 | J8: =(-1)*ScenarioParameters!$B$7/4*(1/1000) -> -210 | K8: =(-1)*ScenarioParameters!$B$7/4*(1/1000) -> -210 | L8: =(-1)*ScenarioParameters!$B$7/4*(1/1000) -> -210 | M8: =(-1)*ScenarioParameters!$B$7/4*(1/1000) -> -210 | ... U8: =(-1)*ScenarioParameters!$B$7/4*(1/1000) -> -210
A9: Production Cost | F9: =(-1)*(ScenarioParameters!$B$5+(ScenarioParameters!$B$5*$B$1))*ScenarioParameters!$G3*(1/1000) -> -393.98815 | G9: =(-1)*(ScenarioParameters!$B$5+(ScenarioParameters!$B$5*$B$1))*ScenarioParameters!$G4*(1/1000) -> -1006.6116 | H9: =(-1)*(ScenarioParameters!$B$5+(ScenarioParameters!$B$5*$B$1))*ScenarioParameters!$G5*(1/1000) -> -781.1826 | I9: =(-1)*(ScenarioParameters!$B$5+(ScenarioParameters!$B$5*$B$1))*ScenarioParameters!$G6*(1/1000) -> -1505.5809 | J9: =(-1)*(ScenarioParameters!$B$5+(ScenarioParameters!$B$5*$B$1))*ScenarioParameters!$G7*(1/1000) -> -826.56702 | K9: =(-1)*(ScenarioParameters!$B$5+(ScenarioParameters!$B$5*$B$1))*ScenarioParameters!$G8*(1/1000) -> -1645.6692 | L9: =(-1)*(ScenarioParameters!$B$5+(ScenarioParameters!$B$5*$B$1))*ScenarioParameters!$G9*(1/1000) -> -1111.0054 | M9: =(-1)*(ScenarioParameters!$B$5+(ScenarioParameters!$B$5*$B$1))*ScenarioParameters!$G10*(1/1000) -> -1976.4469 | N9: =(-1)*(ScenarioParameters!$B$5+(ScenarioParameters!$B$5*$B$1))*ScenarioParameters!$G11*(1/1000) -> -1047.5392 | O9: =(-1)*(ScenarioParameters!$B$5+(ScenarioParameters!$B$5*$B$1))*ScenarioParameters!$G12*(1/1000) -> -2056.2757 | P9: =(-1)*(ScenarioParameters!$B$5+(ScenarioParameters!$B$5*$B$1))*ScenarioParameters!$G13*(1/1000) -> -1365.3756 | Q9: =(-1)*(ScenarioParameters!$B$5+(ScenarioParameters!$B$5*$B$1))*ScenarioParameters!$G14*(1/1000) -> -2402.2913 | R9: =(-1)*(ScenarioParameters!$B$5+(ScenarioParameters!$B$5*$B$1))*ScenarioParameters!$G15*(1/1000) -> -1283.1878 | S9: =(-1)*(ScenarioParameters!$B$5+(ScenarioParameters!$B$5*$B$1))*ScenarioParameters!$G16*(1/1000) -> -2494.2149 | T9: =(-1)*(ScenarioParameters!$B$5+(ScenarioParameters!$B$5*$B$1))*ScenarioParameters!$G16*(1/1000) -> -2494.2149 | U9: =(-1)*(ScenarioParameters!$B$5+(ScenarioParameters!$B$5*$B$1))*ScenarioParameters!$G18*(1/1000) -> -2864.6843
A10: Production volume | F10: =ScenarioParameters!$G3 -> 3106.9661 | G10: =ScenarioParameters!$G4 -> 7938.0762 | H10: =ScenarioParameters!$G5 -> 6160.3574 | I10: =ScenarioParameters!$G6 -> 11872.917 | J10: =ScenarioParameters!$G7 -> 6518.2561 | K10: =ScenarioParameters!$G8 -> 12977.645 | L10: =ScenarioParameters!$G9 -> 8761.3198 | M10: =ScenarioParameters!$G10 -> 15586.137 | N10: =ScenarioParameters!$G11 -> 8260.8289 | O10: =ScenarioParameters!$G12 -> 16215.662 | P10: =ScenarioParameters!$G13 -> 10767.267 | Q10: =ScenarioParameters!$G14 -> 18944.32 | R10: =ScenarioParameters!$G15 -> 10119.139 | S10: =ScenarioParameters!$G16 -> 19669.223 | T10: =ScenarioParameters!$G17 -> 12944.52 | U10: =ScenarioParameters!$G18 -> 22590.723
A11: Unit product cost | F11: =F9/F10 -> -0.126808 | G11: =G9/G10 -> -0.126808 | H11: =H9/H10 -> -0.126808 | I11: =I9/I10 -> -0.126808 | J11: =J9/J10 -> -0.126808 | K11: =K9/K10 -> -0.126808 | L11: =L9/L10 -> -0.126808 | M11: =M9/M10 -> -0.126808 | ... U11: =U9/U10 -> -0.126808
A12: Sales revenue | F12: =(ScenarioParameters!$B$4*F10)*(1/1000) -> 928.98285 | G12: =(ScenarioParameters!$B$4*G10)*(1/1000) -> 2373.4848 | H12: =(ScenarioParameters!$B$4*H10)*(1/1000) -> 1841.9469 | I12: =(ScenarioParameters!$B$4*I10)*(1/1000) -> 3550.0022 | J12: =(ScenarioParameters!$B$4*J10)*(1/1000) -> 1948.9586 | K12: =(ScenarioParameters!$B$4*K10)*(1/1000) -> 3880.3159 | L12: =(ScenarioParameters!$B$4*L10)*(1/1000) -> 2619.6346 | M12: =(ScenarioParameters!$B$4*M10)*(1/1000) -> 4660.255 | ... U12: =(ScenarioParameters!$B$4*U10)*(1/1000) -> 6754.626
A13: Forecasted Sales Volume | F13: =F$10 -> 3106.9661 | G13: =G$10 -> 7938.0762 | H13: =H$10 -> 6160.3574 | I13: =I$10 -> 11872.917 | J13: =J$10 -> 6518.2561 | K13: =K$10 -> 12977.645 | L13: =L$10 -> 8761.3198 | M13: =M$10 -> 15586.137 | ... U13: =U$10 -> 22590.723
A14: Unit price | F14: =F$12/F$13 -> 0.299 | G14: =G$12/G$13 -> 0.299 | H14: =H$12/H$13 -> 0.299 | I14: =I$12/I$13 -> 0.299 | J14: =J$12/J$13 -> 0.299 | K14: =K$12/K$13 -> 0.299 | L14: =L$12/L$13 -> 0.299 | M14: =M$12/M$13 -> 0.299 | ... U14: =U$12/U$13 -> 0.299
A16: Period Cash Flow | B16: =SUM(B6+B7+B8+B9+B12) -> -15.12 | C16: =SUM(C6+C7+C8+C9+C12) -> -15.12 | D16: =SUM(D6+D7+D8+D9+D12) -> -15.12 | E16: =SUM(E6+E7+E8+E9+E12) -> -18.144 | F16: =SUM(F6+F7+F8+F9+F12) -> 321.9707 | G16: =SUM(G6+G7+G8+G9+G12) -> 1156.8732 | H16: =SUM(H6+H7+H8+H9+H12) -> 850.76426 | I16: =SUM(I6+I7+I8+I9+I12) -> 1834.4213 | ... U16: =SUM(U6+U7+U8+U9+U12) -> 3679.9417
A17: Unit Price | B17: =B16 -> -15.12 | C17: =C16/(1+(ScenarioParameters!$B$8/100)/4)^B3 -> -14.859951 | D17: =D16/(1+(ScenarioParameters!$B$8/100)/4)^C3 -> -14.604374 | E17: =E16/(1+(ScenarioParameters!$B$8/100)/4)^D3 -> -17.223832 | F17: =F16/(1+(ScenarioParameters!$B$8/100)/4)^E3 -> 300.3853 | G17: =G16/(1+(ScenarioParameters!$B$8/100)/4)^F3 -> 1060.7516 | H17: =H16/(1+(ScenarioParameters!$B$8/100)/4)^G3 -> 766.65986 | I17: =I16/(1+(ScenarioParameters!$B$8/100)/4)^H3 -> 1624.6438 | J17: =J16/(1+(ScenarioParameters!$B$8/100)/4)^I3 -> 794.15617 | ... U17: =U16/(1+(ScenarioParameters!$B$8/100)/4)^T3 -> 2646.592
A19: Project NVP | B19: =SUM(B17:U17) -> 23066.729
A21: Forecasted Sales Volume from Winter's forecasting method*

Sheet -10 UnitCost
A1: Unit Cost Analysis: | B1: -0.1
B2: Year 0, Development | F2: Year 1, Projection | J2: Year 2, Projection | N2: Year 3, Projection | R2: Year 4, Projection
A3: Period | B3: 1 | C3: =B3+1 -> 2 | D3: =C3+1 -> 3 | E3: =D3+1 -> 4 | F3: =E3+1 -> 5 | G3: =F3+1 -> 6 | H3: =G3+1 -> 7 | I3: =H3+1 -> 8 | J3: =I3+1 -> 9 | ... U3: =T3+1 -> 20
A4: ($Value in thousands) | B4: Q1 | C4: Q2 | D4: Q3 | E4: Q4 | F4: Q1 | G4: Q2 | H4: Q3 | I4: Q4 | J4: Q1 | K4: Q2 | L4: Q3 | M4: Q4 | N4: Q1 | O4: Q2 | P4: Q3 | Q4: Q4 | R4: Q1 | S4: Q2 | T4: Q3 | U4: Q4
A6: Development Cost | B6: =(-1)*ScenarioParameters!$B$3/4*(1/1000) -> -15.12 | C6: =(-1)*ScenarioParameters!$B$3/4*(1/1000) -> -15.12 | D6: =(-1)*ScenarioParameters!$B$3/4*(1/1000) -> -15.12 | E6: =(-1)*ScenarioParameters!$B$3/4*(1/1000) -> -15.12
A7: Ramp-up cost | E7: =(-1)*ScenarioParameters!$B$6/2*(1/1000) -> -3.024 | F7: =(-1)*ScenarioParameters!$B$6/2*(1/1000) -> -3.024
A8: Marketing & support cost | F8: =(-1)*ScenarioParameters!$B$7/4*(1/1000) -> -210 | G8: =(-1)*ScenarioParameters!$B$7/4*(1/1000) -> -210 | H8: =(-1)*ScenarioParameters!$B$7/4*(1/1000) -> -210 | I8: =(-1)*ScenarioParameters!$B$7/4*(1/1000) -> -210 | J8: =(-1)*ScenarioParameters!$B$7/4*(1/1000) -> -210 | K8: =(-1)*ScenarioParameters!$B$7/4*(1/1000) -> -210 | L8: =(-1)*ScenarioParameters!$B$7/4*(1/1000) -> -210 | M8: =(-1)*ScenarioParameters!$B$7/4*(1/1000) -> -210 | ... U8: =(-1)*ScenarioParameters!$B$7/4*(1/1000) -> -210
A9: Production Cost | F9: =(-1)*(ScenarioParameters!$B$5+(ScenarioParameters!$B$5*$B$1))*ScenarioParameters!$G3*(1/1000) -> -322.35394 | G9: =(-1)*(ScenarioParameters!$B$5+(ScenarioParameters!$B$5*$B$1))*ScenarioParameters!$G4*(1/1000) -> -823.59128 | H9: =(-1)*(ScenarioParameters!$B$5+(ScenarioParameters!$B$5*$B$1))*ScenarioParameters!$G5*(1/1000) -> -639.1494 | I9: =(-1)*(ScenarioParameters!$B$5+(ScenarioParameters!$B$5*$B$1))*ScenarioParameters!$G6*(1/1000) -> -1231.8389 | J9: =(-1)*(ScenarioParameters!$B$5+(ScenarioParameters!$B$5*$B$1))*ScenarioParameters!$G7*(1/1000) -> -676.28211 | K9: =(-1)*(ScenarioParameters!$B$5+(ScenarioParameters!$B$5*$B$1))*ScenarioParameters!$G8*(1/1000) -> -1346.4566 | L9: =(-1)*(ScenarioParameters!$B$5+(ScenarioParameters!$B$5*$B$1))*ScenarioParameters!$G9*(1/1000) -> -909.00445 | M9: =(-1)*(ScenarioParameters!$B$5+(ScenarioParameters!$B$5*$B$1))*ScenarioParameters!$G10*(1/1000) -> -1617.0929 | N9: =(-1)*(ScenarioParameters!$B$5+(ScenarioParameters!$B$5*$B$1))*ScenarioParameters!$G11*(1/1000) -> -857.07752 | O9: =(-1)*(ScenarioParameters!$B$5+(ScenarioParameters!$B$5*$B$1))*ScenarioParameters!$G12*(1/1000) -> -1682.4074 | P9: =(-1)*(ScenarioParameters!$B$5+(ScenarioParameters!$B$5*$B$1))*ScenarioParameters!$G13*(1/1000) -> -1117.1255 | Q9: =(-1)*(ScenarioParameters!$B$5+(ScenarioParameters!$B$5*$B$1))*ScenarioParameters!$G14*(1/1000) -> -1965.5111 | R9: =(-1)*(ScenarioParameters!$B$5+(ScenarioParameters!$B$5*$B$1))*ScenarioParameters!$G15*(1/1000) -> -1049.8809 | S9: =(-1)*(ScenarioParameters!$B$5+(ScenarioParameters!$B$5*$B$1))*ScenarioParameters!$G16*(1/1000) -> -2040.7212 | T9: =(-1)*(ScenarioParameters!$B$5+(ScenarioParameters!$B$5*$B$1))*ScenarioParameters!$G16*(1/1000) -> -2040.7212 | U9: =(-1)*(ScenarioParameters!$B$5+(ScenarioParameters!$B$5*$B$1))*ScenarioParameters!$G18*(1/1000) -> -2343.8326
A10: Production volume | F10: =ScenarioParameters!$G3 -> 3106.9661 | G10: =ScenarioParameters!$G4 -> 7938.0762 | H10: =ScenarioParameters!$G5 -> 6160.3574 | I10: =ScenarioParameters!$G6 -> 11872.917 | J10: =ScenarioParameters!$G7 -> 6518.2561 | K10: =ScenarioParameters!$G8 -> 12977.645 | L10: =ScenarioParameters!$G9 -> 8761.3198 | M10: =ScenarioParameters!$G10 -> 15586.137 | N10: =ScenarioParameters!$G11 -> 8260.8289 | O10: =ScenarioParameters!$G12 -> 16215.662 | P10: =ScenarioParameters!$G13 -> 10767.267 | Q10: =ScenarioParameters!$G14 -> 18944.32 | R10: =ScenarioParameters!$G15 -> 10119.139 | S10: =ScenarioParameters!$G16 -> 19669.223 | T10: =ScenarioParameters!$G17 -> 12944.52 | U10: =ScenarioParameters!$G18 -> 22590.723
A11: Unit product cost | F11: =F9/F10 -> -0.103752 | G11: =G9/G10 -> -0.103752 | H11: =H9/H10 -> -0.103752 | I11: =I9/I10 -> -0.103752 | J11: =J9/J10 -> -0.103752 | K11: =K9/K10 -> -0.103752 | L11: =L9/L10 -> -0.103752 | M11: =M9/M10 -> -0.103752 | ... U11: =U9/U10 -> -0.103752
A12: Sales revenue | F12: =(ScenarioParameters!$B$4*F10)*(1/1000) -> 928.98285 | G12: =(ScenarioParameters!$B$4*G10)*(1/1000) -> 2373.4848 | H12: =(ScenarioParameters!$B$4*H10)*(1/1000) -> 1841.9469 | I12: =(ScenarioParameters!$B$4*I10)*(1/1000) -> 3550.0022 | J12: =(ScenarioParameters!$B$4*J10)*(1/1000) -> 1948.9586 | K12: =(ScenarioParameters!$B$4*K10)*(1/1000) -> 3880.3159 | L12: =(ScenarioParameters!$B$4*L10)*(1/1000) -> 2619.6346 | M12: =(ScenarioParameters!$B$4*M10)*(1/1000) -> 4660.255 | ... U12: =(ScenarioParameters!$B$4*U10)*(1/1000) -> 6754.626
A13: Forecasted Sales Volume | F13: =F$10 -> 3106.9661 | G13: =G$10 -> 7938.0762 | H13: =H$10 -> 6160.3574 | I13: =I$10 -> 11872.917 | J13: =J$10 -> 6518.2561 | K13: =K$10 -> 12977.645 | L13: =L$10 -> 8761.3198 | M13: =M$10 -> 15586.137 | ... U13: =U$10 -> 22590.723
A14: Unit price | F14: =F$12/F$13 -> 0.299 | G14: =G$12/G$13 -> 0.299 | H14: =H$12/H$13 -> 0.299 | I14: =I$12/I$13 -> 0.299 | J14: =J$12/J$13 -> 0.299 | K14: =K$12/K$13 -> 0.299 | L14: =L$12/L$13 -> 0.299 | M14: =M$12/M$13 -> 0.299 | ... U14: =U$12/U$13 -> 0.299
A16: Period Cash Flow | B16: =SUM(B6+B7+B8+B9+B12) -> -15.12 | C16: =SUM(C6+C7+C8+C9+C12) -> -15.12 | D16: =SUM(D6+D7+D8+D9+D12) -> -15.12 | E16: =SUM(E6+E7+E8+E9+E12) -> -18.144 | F16: =SUM(F6+F7+F8+F9+F12) -> 393.60491 | G16: =SUM(G6+G7+G8+G9+G12) -> 1339.8935 | H16: =SUM(H6+H7+H8+H9+H12) -> 992.79746 | I16: =SUM(I6+I7+I8+I9+I12) -> 2108.1633 | ... U16: =SUM(U6+U7+U8+U9+U12) -> 4200.7934
A17: Unit Price | B17: =B16 -> -15.12 | C17: =C16/(1+(ScenarioParameters!$B$8/100)/4)^B3 -> -14.859951 | D17: =D16/(1+(ScenarioParameters!$B$8/100)/4)^C3 -> -14.604374 | E17: =E16/(1+(ScenarioParameters!$B$8/100)/4)^D3 -> -17.223832 | F17: =F16/(1+(ScenarioParameters!$B$8/100)/4)^E3 -> 367.21705 | G17: =G16/(1+(ScenarioParameters!$B$8/100)/4)^F3 -> 1228.5652 | H17: =H16/(1+(ScenarioParameters!$B$8/100)/4)^G3 -> 894.65202 | I17: =I16/(1+(ScenarioParameters!$B$8/100)/4)^H3 -> 1867.0817 | J17: =J16/(1+(ScenarioParameters!$B$8/100)/4)^I3 -> 924.96589 | ... U17: =U16/(1+(ScenarioParameters!$B$8/100)/4)^T3 -> 3021.1854
A19: Project NVP | B19: =SUM(B17:U17) -> 26730.665
A21: Forecasted Sales Volume from Winter's forecasting method*

Sheet +20 UnitCost
A1: Unit Cost Analysis: | B1: 0.2
B2: Year 0, Development | F2: Year 1, Projection | J2: Year 2, Projection | N2: Year 3, Projection | R2: Year 4, Projection
A3: Period | B3: 1 | C3: =B3+1 -> 2 | D3: =C3+1 -> 3 | E3: =D3+1 -> 4 | F3: =E3+1 -> 5 | G3: =F3+1 -> 6 | H3: =G3+1 -> 7 | I3: =H3+1 -> 8 | J3: =I3+1 -> 9 | ... U3: =T3+1 -> 20
A4: ($Value in thousands) | B4: Q1 | C4: Q2 | D4: Q3 | E4: Q4 | F4: Q1 | G4: Q2 | H4: Q3 | I4: Q4 | J4: Q1 | K4: Q2 | L4: Q3 | M4: Q4 | N4: Q1 | O4: Q2 | P4: Q3 | Q4: Q4 | R4: Q1 | S4: Q2 | T4: Q3 | U4: Q4
A6: Development Cost | B6: =(-1)*ScenarioParameters!$B$3/4*(1/1000) -> -15.12 | C6: =(-1)*ScenarioParameters!$B$3/4*(1/1000) -> -15.12 | D6: =(-1)*ScenarioParameters!$B$3/4*(1/1000) -> -15.12 | E6: =(-1)*ScenarioParameters!$B$3/4*(1/1000) -> -15.12
A7: Ramp-up cost | E7: =(-1)*ScenarioParameters!$B$6/2*(1/1000) -> -3.024 | F7: =(-1)*ScenarioParameters!$B$6/2*(1/1000) -> -3.024
A8: Marketing & support cost | F8: =(-1)*ScenarioParameters!$B$7/4*(1/1000) -> -210 | G8: =(-1)*ScenarioParameters!$B$7/4*(1/1000) -> -210 | H8: =(-1)*ScenarioParameters!$B$7/4*(1/1000) -> -210 | I8: =(-1)*ScenarioParameters!$B$7/4*(1/1000) -> -210 | J8: =(-1)*ScenarioParameters!$B$7/4*(1/1000) -> -210 | K8: =(-1)*ScenarioParameters!$B$7/4*(1/1000) -> -210 | L8: =(-1)*ScenarioParameters!$B$7/4*(1/1000) -> -210 | M8: =(-1)*ScenarioParameters!$B$7/4*(1/1000) -> -210 | ... U8: =(-1)*ScenarioParameters!$B$7/4*(1/1000) -> -210
A9: Production Cost | F9: =(-1)*(ScenarioParameters!$B$5+(ScenarioParameters!$B$5*$B$1))*ScenarioParameters!$G3*(1/1000) -> -429.80526 | G9: =(-1)*(ScenarioParameters!$B$5+(ScenarioParameters!$B$5*$B$1))*ScenarioParameters!$G4*(1/1000) -> -1098.1217 | H9: =(-1)*(ScenarioParameters!$B$5+(ScenarioParameters!$B$5*$B$1))*ScenarioParameters!$G5*(1/1000) -> -852.1992 | I9: =(-1)*(ScenarioParameters!$B$5+(ScenarioParameters!$B$5*$B$1))*ScenarioParameters!$G6*(1/1000) -> -1642.4519 | J9: =(-1)*(ScenarioParameters!$B$5+(ScenarioParameters!$B$5*$B$1))*ScenarioParameters!$G7*(1/1000) -> -901.70947 | K9: =(-1)*(ScenarioParameters!$B$5+(ScenarioParameters!$B$5*$B$1))*ScenarioParameters!$G8*(1/1000) -> -1795.2755 | L9: =(-1)*(ScenarioParameters!$B$5+(ScenarioParameters!$B$5*$B$1))*ScenarioParameters!$G9*(1/1000) -> -1212.0059 | M9: =(-1)*(ScenarioParameters!$B$5+(ScenarioParameters!$B$5*$B$1))*ScenarioParameters!$G10*(1/1000) -> -2156.1239 | N9: =(-1)*(ScenarioParameters!$B$5+(ScenarioParameters!$B$5*$B$1))*ScenarioParameters!$G11*(1/1000) -> -1142.77 | O9: =(-1)*(ScenarioParameters!$B$5+(ScenarioParameters!$B$5*$B$1))*ScenarioParameters!$G12*(1/1000) -> -2243.2098 | P9: =(-1)*(ScenarioParameters!$B$5+(ScenarioParameters!$B$5*$B$1))*ScenarioParameters!$G13*(1/1000) -> -1489.5007 | Q9: =(-1)*(ScenarioParameters!$B$5+(ScenarioParameters!$B$5*$B$1))*ScenarioParameters!$G14*(1/1000) -> -2620.6814 | R9: =(-1)*(ScenarioParameters!$B$5+(ScenarioParameters!$B$5*$B$1))*ScenarioParameters!$G15*(1/1000) -> -1399.8412 | S9: =(-1)*(ScenarioParameters!$B$5+(ScenarioParameters!$B$5*$B$1))*ScenarioParameters!$G16*(1/1000) -> -2720.9617 | T9: =(-1)*(ScenarioParameters!$B$5+(ScenarioParameters!$B$5*$B$1))*ScenarioParameters!$G16*(1/1000) -> -2720.9617 | U9: =(-1)*(ScenarioParameters!$B$5+(ScenarioParameters!$B$5*$B$1))*ScenarioParameters!$G18*(1/1000) -> -3125.1102
A10: Production volume | F10: =ScenarioParameters!$G3 -> 3106.9661 | G10: =ScenarioParameters!$G4 -> 7938.0762 | H10: =ScenarioParameters!$G5 -> 6160.3574 | I10: =ScenarioParameters!$G6 -> 11872.917 | J10: =ScenarioParameters!$G7 -> 6518.2561 | K10: =ScenarioParameters!$G8 -> 12977.645 | L10: =ScenarioParameters!$G9 -> 8761.3198 | M10: =ScenarioParameters!$G10 -> 15586.137 | N10: =ScenarioParameters!$G11 -> 8260.8289 | O10: =ScenarioParameters!$G12 -> 16215.662 | P10: =ScenarioParameters!$G13 -> 10767.267 | Q10: =ScenarioParameters!$G14 -> 18944.32 | R10: =ScenarioParameters!$G15 -> 10119.139 | S10: =ScenarioParameters!$G16 -> 19669.223 | T10: =ScenarioParameters!$G17 -> 12944.52 | U10: =ScenarioParameters!$G18 -> 22590.723
A11: Unit product cost | F11: =F9/F10 -> -0.138336 | G11: =G9/G10 -> -0.138336 | H11: =H9/H10 -> -0.138336 | I11: =I9/I10 -> -0.138336 | J11: =J9/J10 -> -0.138336 | K11: =K9/K10 -> -0.138336 | L11: =L9/L10 -> -0.138336 | M11: =M9/M10 -> -0.138336 | ... U11: =U9/U10 -> -0.138336
A12: Sales revenue | F12: =(ScenarioParameters!$B$4*F10)*(1/1000) -> 928.98285 | G12: =(ScenarioParameters!$B$4*G10)*(1/1000) -> 2373.4848 | H12: =(ScenarioParameters!$B$4*H10)*(1/1000) -> 1841.9469 | I12: =(ScenarioParameters!$B$4*I10)*(1/1000) -> 3550.0022 | J12: =(ScenarioParameters!$B$4*J10)*(1/1000) -> 1948.9586 | K12: =(ScenarioParameters!$B$4*K10)*(1/1000) -> 3880.3159 | L12: =(ScenarioParameters!$B$4*L10)*(1/1000) -> 2619.6346 | M12: =(ScenarioParameters!$B$4*M10)*(1/1000) -> 4660.255 | ... U12: =(ScenarioParameters!$B$4*U10)*(1/1000) -> 6754.626
A13: Forecasted Sales Volume | F13: =F$10 -> 3106.9661 | G13: =G$10 -> 7938.0762 | H13: =H$10 -> 6160.3574 | I13: =I$10 -> 11872.917 | J13: =J$10 -> 6518.2561 | K13: =K$10 -> 12977.645 | L13: =L$10 -> 8761.3198 | M13: =M$10 -> 15586.137 | ... U13: =U$10 -> 22590.723
A14: Unit price | F14: =F$12/F$13 -> 0.299 | G14: =G$12/G$13 -> 0.299 | H14: =H$12/H$13 -> 0.299 | I14: =I$12/I$13 -> 0.299 | J14: =J$12/J$13 -> 0.299 | K14: =K$12/K$13 -> 0.299 | L14: =L$12/L$13 -> 0.299 | M14: =M$12/M$13 -> 0.299 | ... U14: =U$12/U$13 -> 0.299
A16: Period Cash Flow | B16: =SUM(B6+B7+B8+B9+B12) -> -15.12 | C16: =SUM(C6+C7+C8+C9+C12) -> -15.12 | D16: =SUM(D6+D7+D8+D9+D12) -> -15.12 | E16: =SUM(E6+E7+E8+E9+E12) -> -18.144 | F16: =SUM(F6+F7+F8+F9+F12) -> 286.1536 | G16: =SUM(G6+G7+G8+G9+G12) -> 1065.3631 | H16: =SUM(H6+H7+H8+H9+H12) -> 779.74766 | I16: =SUM(I6+I7+I8+I9+I12) -> 1697.5504 | ... U16: =SUM(U6+U7+U8+U9+U12) -> 3419.5158
A17: Unit Price | B17: =B16 -> -15.12 | C17: =C16/(1+(ScenarioParameters!$B$8/100)/4)^B3 -> -14.859951 | D17: =D16/(1+(ScenarioParameters!$B$8/100)/4)^C3 -> -14.604374 | E17: =E16/(1+(ScenarioParameters!$B$8/100)/4)^D3 -> -17.223832 | F17: =F16/(1+(ScenarioParameters!$B$8/100)/4)^E3 -> 266.96943 | G17: =G16/(1+(ScenarioParameters!$B$8/100)/4)^F3 -> 976.84476 | H17: =H16/(1+(ScenarioParameters!$B$8/100)/4)^G3 -> 702.66378 | I17: =I16/(1+(ScenarioParameters!$B$8/100)/4)^H3 -> 1503.4249 | J17: =J16/(1+(ScenarioParameters!$B$8/100)/4)^I3 -> 728.7513 | ... U17: =U16/(1+(ScenarioParameters!$B$8/100)/4)^T3 -> 2459.2953
A19: Project NVP | B19: =SUM(B17:U17) -> 21234.76
A21: Forecasted Sales Volume from Winter's forecasting method*

Sheet -20 UnitCost
A1: Unit Cost Analysis: | B1: -0.2
B2: Year 0, Development | F2: Year 1, Projection | J2: Year 2, Projection | N2: Year 3, Projection | R2: Year 4, Projection
A3: Period | B3: 1 | C3: =B3+1 -> 2 | D3: =C3+1 -> 3 | E3: =D3+1 -> 4 | F3: =E3+1 -> 5 | G3: =F3+1 -> 6 | H3: =G3+1 -> 7 | I3: =H3+1 -> 8 | J3: =I3+1 -> 9 | ... U3: =T3+1 -> 20
A4: ($Value in thousands) | B4: Q1 | C4: Q2 | D4: Q3 | E4: Q4 | F4: Q1 | G4: Q2 | H4: Q3 | I4: Q4 | J4: Q1 | K4: Q2 | L4: Q3 | M4: Q4 | N4: Q1 | O4: Q2 | P4: Q3 | Q4: Q4 | R4: Q1 | S4: Q2 | T4: Q3 | U4: Q4
A6: Development Cost | B6: =(-1)*ScenarioParameters!$B$3/4*(1/1000) -> -15.12 | C6: =(-1)*ScenarioParameters!$B$3/4*(1/1000) -> -15.12 | D6: =(-1)*ScenarioParameters!$B$3/4*(1/1000) -> -15.12 | E6: =(-1)*ScenarioParameters!$B$3/4*(1/1000) -> -15.12
A7: Ramp-up cost | E7: =(-1)*ScenarioParameters!$B$6/2*(1/1000) -> -3.024 | F7: =(-1)*ScenarioParameters!$B$6/2*(1/1000) -> -3.024
A8: Marketing & support cost | F8: =(-1)*ScenarioParameters!$B$7/4*(1/1000) -> -210 | G8: =(-1)*ScenarioParameters!$B$7/4*(1/1000) -> -210 | H8: =(-1)*ScenarioParameters!$B$7/4*(1/1000) -> -210 | I8: =(-1)*ScenarioParameters!$B$7/4*(1/1000) -> -210 | J8: =(-1)*ScenarioParameters!$B$7/4*(1/1000) -> -210 | K8: =(-1)*ScenarioParameters!$B$7/4*(1/1000) -> -210 | L8: =(-1)*ScenarioParameters!$B$7/4*(1/1000) -> -210 | M8: =(-1)*ScenarioParameters!$B$7/4*(1/1000) -> -210 | ... U8: =(-1)*ScenarioParameters!$B$7/4*(1/1000) -> -210
A9: Production Cost | F9: =(-1)*(ScenarioParameters!$B$5+(ScenarioParameters!$B$5*$B$1))*ScenarioParameters!$G3*(1/1000) -> -286.53684 | G9: =(-1)*(ScenarioParameters!$B$5+(ScenarioParameters!$B$5*$B$1))*ScenarioParameters!$G4*(1/1000) -> -732.08114 | H9: =(-1)*(ScenarioParameters!$B$5+(ScenarioParameters!$B$5*$B$1))*ScenarioParameters!$G5*(1/1000) -> -568.1328 | I9: =(-1)*(ScenarioParameters!$B$5+(ScenarioParameters!$B$5*$B$1))*ScenarioParameters!$G6*(1/1000) -> -1094.9679 | J9: =(-1)*(ScenarioParameters!$B$5+(ScenarioParameters!$B$5*$B$1))*ScenarioParameters!$G7*(1/1000) -> -601.13965 | K9: =(-1)*(ScenarioParameters!$B$5+(ScenarioParameters!$B$5*$B$1))*ScenarioParameters!$G8*(1/1000) -> -1196.8504 | L9: =(-1)*(ScenarioParameters!$B$5+(ScenarioParameters!$B$5*$B$1))*ScenarioParameters!$G9*(1/1000) -> -808.00395 | M9: =(-1)*(ScenarioParameters!$B$5+(ScenarioParameters!$B$5*$B$1))*ScenarioParameters!$G10*(1/1000) -> -1437.4159 | N9: =(-1)*(ScenarioParameters!$B$5+(ScenarioParameters!$B$5*$B$1))*ScenarioParameters!$G11*(1/1000) -> -761.84669 | O9: =(-1)*(ScenarioParameters!$B$5+(ScenarioParameters!$B$5*$B$1))*ScenarioParameters!$G12*(1/1000) -> -1495.4732 | P9: =(-1)*(ScenarioParameters!$B$5+(ScenarioParameters!$B$5*$B$1))*ScenarioParameters!$G13*(1/1000) -> -993.00045 | Q9: =(-1)*(ScenarioParameters!$B$5+(ScenarioParameters!$B$5*$B$1))*ScenarioParameters!$G14*(1/1000) -> -1747.121 | R9: =(-1)*(ScenarioParameters!$B$5+(ScenarioParameters!$B$5*$B$1))*ScenarioParameters!$G15*(1/1000) -> -933.22747 | S9: =(-1)*(ScenarioParameters!$B$5+(ScenarioParameters!$B$5*$B$1))*ScenarioParameters!$G16*(1/1000) -> -1813.9744 | T9: =(-1)*(ScenarioParameters!$B$5+(ScenarioParameters!$B$5*$B$1))*ScenarioParameters!$G16*(1/1000) -> -1813.9744 | U9: =(-1)*(ScenarioParameters!$B$5+(ScenarioParameters!$B$5*$B$1))*ScenarioParameters!$G18*(1/1000) -> -2083.4068
A10: Production volume | F10: =ScenarioParameters!$G3 -> 3106.9661 | G10: =ScenarioParameters!$G4 -> 7938.0762 | H10: =ScenarioParameters!$G5 -> 6160.3574 | I10: =ScenarioParameters!$G6 -> 11872.917 | J10: =ScenarioParameters!$G7 -> 6518.2561 | K10: =ScenarioParameters!$G8 -> 12977.645 | L10: =ScenarioParameters!$G9 -> 8761.3198 | M10: =ScenarioParameters!$G10 -> 15586.137 | N10: =ScenarioParameters!$G11 -> 8260.8289 | O10: =ScenarioParameters!$G12 -> 16215.662 | P10: =ScenarioParameters!$G13 -> 10767.267 | Q10: =ScenarioParameters!$G14 -> 18944.32 | R10: =ScenarioParameters!$G15 -> 10119.139 | S10: =ScenarioParameters!$G16 -> 19669.223 | T10: =ScenarioParameters!$G17 -> 12944.52 | U10: =ScenarioParameters!$G18 -> 22590.723
A11: Unit product cost | F11: =F9/F10 -> -0.092224 | G11: =G9/G10 -> -0.092224 | H11: =H9/H10 -> -0.092224 | I11: =I9/I10 -> -0.092224 | J11: =J9/J10 -> -0.092224 | K11: =K9/K10 -> -0.092224 | L11: =L9/L10 -> -0.092224 | M11: =M9/M10 -> -0.092224 | ... U11: =U9/U10 -> -0.092224
A12: Sales revenue | F12: =(ScenarioParameters!$B$4*F10)*(1/1000) -> 928.98285 | G12: =(ScenarioParameters!$B$4*G10)*(1/1000) -> 2373.4848 | H12: =(ScenarioParameters!$B$4*H10)*(1/1000) -> 1841.9469 | I12: =(ScenarioParameters!$B$4*I10)*(1/1000) -> 3550.0022 | J12: =(ScenarioParameters!$B$4*J10)*(1/1000) -> 1948.9586 | K12: =(ScenarioParameters!$B$4*K10)*(1/1000) -> 3880.3159 | L12: =(ScenarioParameters!$B$4*L10)*(1/1000) -> 2619.6346 | M12: =(ScenarioParameters!$B$4*M10)*(1/1000) -> 4660.255 | ... U12: =(ScenarioParameters!$B$4*U10)*(1/1000) -> 6754.626
A13: Forecasted Sales Volume | F13: =F$10 -> 3106.9661 | G13: =G$10 -> 7938.0762 | H13: =H$10 -> 6160.3574 | I13: =I$10 -> 11872.917 | J13: =J$10 -> 6518.2561 | K13: =K$10 -> 12977.645 | L13: =L$10 -> 8761.3198 | M13: =M$10 -> 15586.137 | ... U13: =U$10 -> 22590.723
A14: Unit price | F14: =F$12/F$13 -> 0.299 | G14: =G$12/G$13 -> 0.299 | H14: =H$12/H$13 -> 0.299 | I14: =I$12/I$13 -> 0.299 | J14: =J$12/J$13 -> 0.299 | K14: =K$12/K$13 -> 0.299 | L14: =L$12/L$13 -> 0.299 | M14: =M$12/M$13 -> 0.299 | ... U14: =U$12/U$13 -> 0.299
A16: Period Cash Flow | B16: =SUM(B6+B7+B8+B9+B12) -> -15.12 | C16: =SUM(C6+C7+C8+C9+C12) -> -15.12 | D16: =SUM(D6+D7+D8+D9+D12) -> -15.12 | E16: =SUM(E6+E7+E8+E9+E12) -> -18.144 | F16: =SUM(F6+F7+F8+F9+F12) -> 429.42202 | G16: =SUM(G6+G7+G8+G9+G12) -> 1431.4036 | H16: =SUM(H6+H7+H8+H9+H12) -> 1063.8141 | I16: =SUM(I6+I7+I8+I9+I12) -> 2245.0343 | ... U16: =SUM(U6+U7+U8+U9+U12) -> 4461.2192
A17: Unit Price | B17: =B16 -> -15.12 | C17: =C16/(1+(ScenarioParameters!$B$8/100)/4)^B3 -> -14.859951 | D17: =D16/(1+(ScenarioParameters!$B$8/100)/4)^C3 -> -14.604374 | E17: =E16/(1+(ScenarioParameters!$B$8/100)/4)^D3 -> -17.223832 | F17: =F16/(1+(ScenarioParameters!$B$8/100)/4)^E3 -> 400.63292 | G17: =G16/(1+(ScenarioParameters!$B$8/100)/4)^F3 -> 1312.472 | H17: =H16/(1+(ScenarioParameters!$B$8/100)/4)^G3 -> 958.6481 | I17: =I16/(1+(ScenarioParameters!$B$8/100)/4)^H3 -> 1988.3007 | J17: =J16/(1+(ScenarioParameters!$B$8/100)/4)^I3 -> 990.37076 | ... U17: =U16/(1+(ScenarioParameters!$B$8/100)/4)^T3 -> 3208.4821
A19: Project NVP | B19: =SUM(B17:U17) -> 28562.633
A21: Forecasted Sales Volume from Winter's forecasting method*

Sheet +30 UnitCost
A1: Unit Cost Analysis: | B1: 0.3
B2: Year 0, Development | F2: Year 1, Projection | J2: Year 2, Projection | N2: Year 3, Projection | R2: Year 4, Projection
A3: Period | B3: 1 | C3: =B3+1 -> 2 | D3: =C3+1 -> 3 | E3: =D3+1 -> 4 | F3: =E3+1 -> 5 | G3: =F3+1 -> 6 | H3: =G3+1 -> 7 | I3: =H3+1 -> 8 | J3: =I3+1 -> 9 | ... U3: =T3+1 -> 20
A4: ($Value in thousands) | B4: Q1 | C4: Q2 | D4: Q3 | E4: Q4 | F4: Q1 | G4: Q2 | H4: Q3 | I4: Q4 | J4: Q1 | K4: Q2 | L4: Q3 | M4: Q4 | N4: Q1 | O4: Q2 | P4: Q3 | Q4: Q4 | R4: Q1 | S4: Q2 | T4: Q3 | U4: Q4
A6: Development Cost | B6: =(-1)*ScenarioParameters!$B$3/4*(1/1000) -> -15.12 | C6: =(-1)*ScenarioParameters!$B$3/4*(1/1000) -> -15.12 | D6: =(-1)*ScenarioParameters!$B$3/4*(1/1000) -> -15.12 | E6: =(-1)*ScenarioParameters!$B$3/4*(1/1000) -> -15.12
A7: Ramp-up cost | E7: =(-1)*ScenarioParameters!$B$6/2*(1/1000) -> -3.024 | F7: =(-1)*ScenarioParameters!$B$6/2*(1/1000) -> -3.024
A8: Marketing & support cost | F8: =(-1)*ScenarioParameters!$B$7/4*(1/1000) -> -210 | G8: =(-1)*ScenarioParameters!$B$7/4*(1/1000) -> -210 | H8: =(-1)*ScenarioParameters!$B$7/4*(1/1000) -> -210 | I8: =(-1)*ScenarioParameters!$B$7/4*(1/1000) -> -210 | J8: =(-1)*ScenarioParameters!$B$7/4*(1/1000) -> -210 | K8: =(-1)*ScenarioParameters!$B$7/4*(1/1000) -> -210 | L8: =(-1)*ScenarioParameters!$B$7/4*(1/1000) -> -210 | M8: =(-1)*ScenarioParameters!$B$7/4*(1/1000) -> -210 | ... U8: =(-1)*ScenarioParameters!$B$7/4*(1/1000) -> -210
A9: Production Cost | F9: =(-1)*(ScenarioParameters!$B$5+(ScenarioParameters!$B$5*$B$1))*ScenarioParameters!$G3*(1/1000) -> -465.62236 | G9: =(-1)*(ScenarioParameters!$B$5+(ScenarioParameters!$B$5*$B$1))*ScenarioParameters!$G4*(1/1000) -> -1189.6319 | H9: =(-1)*(ScenarioParameters!$B$5+(ScenarioParameters!$B$5*$B$1))*ScenarioParameters!$G5*(1/1000) -> -923.2158 | I9: =(-1)*(ScenarioParameters!$B$5+(ScenarioParameters!$B$5*$B$1))*ScenarioParameters!$G6*(1/1000) -> -1779.3228 | J9: =(-1)*(ScenarioParameters!$B$5+(ScenarioParameters!$B$5*$B$1))*ScenarioParameters!$G7*(1/1000) -> -976.85193 | K9: =(-1)*(ScenarioParameters!$B$5+(ScenarioParameters!$B$5*$B$1))*ScenarioParameters!$G8*(1/1000) -> -1944.8818 | L9: =(-1)*(ScenarioParameters!$B$5+(ScenarioParameters!$B$5*$B$1))*ScenarioParameters!$G9*(1/1000) -> -1313.0064 | M9: =(-1)*(ScenarioParameters!$B$5+(ScenarioParameters!$B$5*$B$1))*ScenarioParameters!$G10*(1/1000) -> -2335.8009 | N9: =(-1)*(ScenarioParameters!$B$5+(ScenarioParameters!$B$5*$B$1))*ScenarioParameters!$G11*(1/1000) -> -1238.0009 | O9: =(-1)*(ScenarioParameters!$B$5+(ScenarioParameters!$B$5*$B$1))*ScenarioParameters!$G12*(1/1000) -> -2430.144 | P9: =(-1)*(ScenarioParameters!$B$5+(ScenarioParameters!$B$5*$B$1))*ScenarioParameters!$G13*(1/1000) -> -1613.6257 | Q9: =(-1)*(ScenarioParameters!$B$5+(ScenarioParameters!$B$5*$B$1))*ScenarioParameters!$G14*(1/1000) -> -2839.0716 | R9: =(-1)*(ScenarioParameters!$B$5+(ScenarioParameters!$B$5*$B$1))*ScenarioParameters!$G15*(1/1000) -> -1516.4946 | S9: =(-1)*(ScenarioParameters!$B$5+(ScenarioParameters!$B$5*$B$1))*ScenarioParameters!$G16*(1/1000) -> -2947.7085 | T9: =(-1)*(ScenarioParameters!$B$5+(ScenarioParameters!$B$5*$B$1))*ScenarioParameters!$G16*(1/1000) -> -2947.7085 | U9: =(-1)*(ScenarioParameters!$B$5+(ScenarioParameters!$B$5*$B$1))*ScenarioParameters!$G18*(1/1000) -> -3385.536
A10: Production volume | F10: =ScenarioParameters!$G3 -> 3106.9661 | G10: =ScenarioParameters!$G4 -> 7938.0762 | H10: =ScenarioParameters!$G5 -> 6160.3574 | I10: =ScenarioParameters!$G6 -> 11872.917 | J10: =ScenarioParameters!$G7 -> 6518.2561 | K10: =ScenarioParameters!$G8 -> 12977.645 | L10: =ScenarioParameters!$G9 -> 8761.3198 | M10: =ScenarioParameters!$G10 -> 15586.137 | N10: =ScenarioParameters!$G11 -> 8260.8289 | O10: =ScenarioParameters!$G12 -> 16215.662 | P10: =ScenarioParameters!$G13 -> 10767.267 | Q10: =ScenarioParameters!$G14 -> 18944.32 | R10: =ScenarioParameters!$G15 -> 10119.139 | S10: =ScenarioParameters!$G16 -> 19669.223 | T10: =ScenarioParameters!$G17 -> 12944.52 | U10: =ScenarioParameters!$G18 -> 22590.723
A11: Unit product cost | F11: =F9/F10 -> -0.149864 | G11: =G9/G10 -> -0.149864 | H11: =H9/H10 -> -0.149864 | I11: =I9/I10 -> -0.149864 | J11: =J9/J10 -> -0.149864 | K11: =K9/K10 -> -0.149864 | L11: =L9/L10 -> -0.149864 | M11: =M9/M10 -> -0.149864 | ... U11: =U9/U10 -> -0.149864
A12: Sales revenue | F12: =(ScenarioParameters!$B$4*F10)*(1/1000) -> 928.98285 | G12: =(ScenarioParameters!$B$4*G10)*(1/1000) -> 2373.4848 | H12: =(ScenarioParameters!$B$4*H10)*(1/1000) -> 1841.9469 | I12: =(ScenarioParameters!$B$4*I10)*(1/1000) -> 3550.0022 | J12: =(ScenarioParameters!$B$4*J10)*(1/1000) -> 1948.9586 | K12: =(ScenarioParameters!$B$4*K10)*(1/1000) -> 3880.3159 | L12: =(ScenarioParameters!$B$4*L10)*(1/1000) -> 2619.6346 | M12: =(ScenarioParameters!$B$4*M10)*(1/1000) -> 4660.255 | ... U12: =(ScenarioParameters!$B$4*U10)*(1/1000) -> 6754.626
A13: Forecasted Sales Volume | F13: =F$10 -> 3106.9661 | G13: =G$10 -> 7938.0762 | H13: =H$10 -> 6160.3574 | I13: =I$10 -> 11872.917 | J13: =J$10 -> 6518.2561 | K13: =K$10 -> 12977.645 | L13: =L$10 -> 8761.3198 | M13: =M$10 -> 15586.137 | ... U13: =U$10 -> 22590.723
A14: Unit price | F14: =F$12/F$13 -> 0.299 | G14: =G$12/G$13 -> 0.299 | H14: =H$12/H$13 -> 0.299 | I14: =I$12/I$13 -> 0.299 | J14: =J$12/J$13 -> 0.299 | K14: =K$12/K$13 -> 0.299 | L14: =L$12/L$13 -> 0.299 | M14: =M$12/M$13 -> 0.299 | ... U14: =U$12/U$13 -> 0.299
A16: Period Cash Flow | B16: =SUM(B6+B7+B8+B9+B12) -> -15.12 | C16: =SUM(C6+C7+C8+C9+C12) -> -15.12 | D16: =SUM(D6+D7+D8+D9+D12) -> -15.12 | E16: =SUM(E6+E7+E8+E9+E12) -> -18.144 | F16: =SUM(F6+F7+F8+F9+F12) -> 250.33649 | G16: =SUM(G6+G7+G8+G9+G12) -> 973.85294 | H16: =SUM(H6+H7+H8+H9+H12) -> 708.73106 | I16: =SUM(I6+I7+I8+I9+I12) -> 1560.6794 | ... U16: =SUM(U6+U7+U8+U9+U12) -> 3159.09
A17: Unit Price | B17: =B16 -> -15.12 | C17: =C16/(1+(ScenarioParameters!$B$8/100)/4)^B3 -> -14.859951 | D17: =D16/(1+(ScenarioParameters!$B$8/100)/4)^C3 -> -14.604374 | E17: =E16/(1+(ScenarioParameters!$B$8/100)/4)^D3 -> -17.223832 | F17: =F16/(1+(ScenarioParameters!$B$8/100)/4)^E3 -> 233.55356 | G17: =G16/(1+(ScenarioParameters!$B$8/100)/4)^F3 -> 892.93797 | H17: =H16/(1+(ScenarioParameters!$B$8/100)/4)^G3 -> 638.66771 | I17: =I16/(1+(ScenarioParameters!$B$8/100)/4)^H3 -> 1382.206 | J17: =J16/(1+(ScenarioParameters!$B$8/100)/4)^I3 -> 663.34644 | ... U17: =U16/(1+(ScenarioParameters!$B$8/100)/4)^T3 -> 2271.9986
A19: Project NVP | B19: =SUM(B17:U17) -> 19402.792
A21: Forecasted Sales Volume from Winter's forecasting method*

Sheet -30 UnitCost
A1: Unit Cost Analysis: | B1: -0.3
B2: Year 0, Development | F2: Year 1, Projection | J2: Year 2, Projection | N2: Year 3, Projection | R2: Year 4, Projection
A3: Period | B3: 1 | C3: =B3+1 -> 2 | D3: =C3+1 -> 3 | E3: =D3+1 -> 4 | F3: =E3+1 -> 5 | G3: =F3+1 -> 6 | H3: =G3+1 -> 7 | I3: =H3+1 -> 8 | J3: =I3+1 -> 9 | ... U3: =T3+1 -> 20
A4: ($Value in thousands) | B4: Q1 | C4: Q2 | D4: Q3 | E4: Q4 | F4: Q1 | G4: Q2 | H4: Q3 | I4: Q4 | J4: Q1 | K4: Q2 | L4: Q3 | M4: Q4 | N4: Q1 | O4: Q2 | P4: Q3 | Q4: Q4 | R4: Q1 | S4: Q2 | T4: Q3 | U4: Q4
A6: Development Cost | B6: =(-1)*ScenarioParameters!$B$3/4*(1/1000) -> -15.12 | C6: =(-1)*ScenarioParameters!$B$3/4*(1/1000) -> -15.12 | D6: =(-1)*ScenarioParameters!$B$3/4*(1/1000) -> -15.12 | E6: =(-1)*ScenarioParameters!$B$3/4*(1/1000) -> -15.12
A7: Ramp-up cost | E7: =(-1)*ScenarioParameters!$B$6/2*(1/1000) -> -3.024 | F7: =(-1)*ScenarioParameters!$B$6/2*(1/1000) -> -3.024
A8: Marketing & support cost | F8: =(-1)*ScenarioParameters!$B$7/4*(1/1000) -> -210 | G8: =(-1)*ScenarioParameters!$B$7/4*(1/1000) -> -210 | H8: =(-1)*ScenarioParameters!$B$7/4*(1/1000) -> -210 | I8: =(-1)*ScenarioParameters!$B$7/4*(1/1000) -> -210 | J8: =(-1)*ScenarioParameters!$B$7/4*(1/1000) -> -210 | K8: =(-1)*ScenarioParameters!$B$7/4*(1/1000) -> -210 | L8: =(-1)*ScenarioParameters!$B$7/4*(1/1000) -> -210 | M8: =(-1)*ScenarioParameters!$B$7/4*(1/1000) -> -210 | ... U8: =(-1)*ScenarioParameters!$B$7/4*(1/1000) -> -210
A9: Production Cost | F9: =(-1)*(ScenarioParameters!$B$5+(ScenarioParameters!$B$5*$B$1))*ScenarioParameters!$G3*(1/1000) -> -250.71973 | G9: =(-1)*(ScenarioParameters!$B$5+(ScenarioParameters!$B$5*$B$1))*ScenarioParameters!$G4*(1/1000) -> -640.571 | H9: =(-1)*(ScenarioParameters!$B$5+(ScenarioParameters!$B$5*$B$1))*ScenarioParameters!$G5*(1/1000) -> -497.1162 | I9: =(-1)*(ScenarioParameters!$B$5+(ScenarioParameters!$B$5*$B$1))*ScenarioParameters!$G6*(1/1000) -> -958.09692 | J9: =(-1)*(ScenarioParameters!$B$5+(ScenarioParameters!$B$5*$B$1))*ScenarioParameters!$G7*(1/1000) -> -525.99719 | K9: =(-1)*(ScenarioParameters!$B$5+(ScenarioParameters!$B$5*$B$1))*ScenarioParameters!$G8*(1/1000) -> -1047.2441 | L9: =(-1)*(ScenarioParameters!$B$5+(ScenarioParameters!$B$5*$B$1))*ScenarioParameters!$G9*(1/1000) -> -707.00346 | M9: =(-1)*(ScenarioParameters!$B$5+(ScenarioParameters!$B$5*$B$1))*ScenarioParameters!$G10*(1/1000) -> -1257.7389 | N9: =(-1)*(ScenarioParameters!$B$5+(ScenarioParameters!$B$5*$B$1))*ScenarioParameters!$G11*(1/1000) -> -666.61585 | O9: =(-1)*(ScenarioParameters!$B$5+(ScenarioParameters!$B$5*$B$1))*ScenarioParameters!$G12*(1/1000) -> -1308.5391 | P9: =(-1)*(ScenarioParameters!$B$5+(ScenarioParameters!$B$5*$B$1))*ScenarioParameters!$G13*(1/1000) -> -868.8754 | Q9: =(-1)*(ScenarioParameters!$B$5+(ScenarioParameters!$B$5*$B$1))*ScenarioParameters!$G14*(1/1000) -> -1528.7308 | R9: =(-1)*(ScenarioParameters!$B$5+(ScenarioParameters!$B$5*$B$1))*ScenarioParameters!$G15*(1/1000) -> -816.57403 | S9: =(-1)*(ScenarioParameters!$B$5+(ScenarioParameters!$B$5*$B$1))*ScenarioParameters!$G16*(1/1000) -> -1587.2276 | T9: =(-1)*(ScenarioParameters!$B$5+(ScenarioParameters!$B$5*$B$1))*ScenarioParameters!$G16*(1/1000) -> -1587.2276 | U9: =(-1)*(ScenarioParameters!$B$5+(ScenarioParameters!$B$5*$B$1))*ScenarioParameters!$G18*(1/1000) -> -1822.9809
A10: Production volume | F10: =ScenarioParameters!$G3 -> 3106.9661 | G10: =ScenarioParameters!$G4 -> 7938.0762 | H10: =ScenarioParameters!$G5 -> 6160.3574 | I10: =ScenarioParameters!$G6 -> 11872.917 | J10: =ScenarioParameters!$G7 -> 6518.2561 | K10: =ScenarioParameters!$G8 -> 12977.645 | L10: =ScenarioParameters!$G9 -> 8761.3198 | M10: =ScenarioParameters!$G10 -> 15586.137 | N10: =ScenarioParameters!$G11 -> 8260.8289 | O10: =ScenarioParameters!$G12 -> 16215.662 | P10: =ScenarioParameters!$G13 -> 10767.267 | Q10: =ScenarioParameters!$G14 -> 18944.32 | R10: =ScenarioParameters!$G15 -> 10119.139 | S10: =ScenarioParameters!$G16 -> 19669.223 | T10: =ScenarioParameters!$G17 -> 12944.52 | U10: =ScenarioParameters!$G18 -> 22590.723
A11: Unit product cost | F11: =F9/F10 -> -0.080696 | G11: =G9/G10 -> -0.080696 | H11: =H9/H10 -> -0.080696 | I11: =I9/I10 -> -0.080696 | J11: =J9/J10 -> -0.080696 | K11: =K9/K10 -> -0.080696 | L11: =L9/L10 -> -0.080696 | M11: =M9/M10 -> -0.080696 | ... U11: =U9/U10 -> -0.080696
A12: Sales revenue | F12: =(ScenarioParameters!$B$4*F10)*(1/1000) -> 928.98285 | G12: =(ScenarioParameters!$B$4*G10)*(1/1000) -> 2373.4848 | H12: =(ScenarioParameters!$B$4*H10)*(1/1000) -> 1841.9469 | I12: =(ScenarioParameters!$B$4*I10)*(1/1000) -> 3550.0022 | J12: =(ScenarioParameters!$B$4*J10)*(1/1000) -> 1948.9586 | K12: =(ScenarioParameters!$B$4*K10)*(1/1000) -> 3880.3159 | L12: =(ScenarioParameters!$B$4*L10)*(1/1000) -> 2619.6346 | M12: =(ScenarioParameters!$B$4*M10)*(1/1000) -> 4660.255 | ... U12: =(ScenarioParameters!$B$4*U10)*(1/1000) -> 6754.626
A13: Forecasted Sales Volume | F13: =F$10 -> 3106.9661 | G13: =G$10 -> 7938.0762 | H13: =H$10 -> 6160.3574 | I13: =I$10 -> 11872.917 | J13: =J$10 -> 6518.2561 | K13: =K$10 -> 12977.645 | L13: =L$10 -> 8761.3198 | M13: =M$10 -> 15586.137 | ... U13: =U$10 -> 22590.723
A14: Unit price | F14: =F$12/F$13 -> 0.299 | G14: =G$12/G$13 -> 0.299 | H14: =H$12/H$13 -> 0.299 | I14: =I$12/I$13 -> 0.299 | J14: =J$12/J$13 -> 0.299 | K14: =K$12/K$13 -> 0.299 | L14: =L$12/L$13 -> 0.299 | M14: =M$12/M$13 -> 0.299 | ... U14: =U$12/U$13 -> 0.299
A16: Period Cash Flow | B16: =SUM(B6+B7+B8+B9+B12) -> -15.12 | C16: =SUM(C6+C7+C8+C9+C12) -> -15.12 | D16: =SUM(D6+D7+D8+D9+D12) -> -15.12 | E16: =SUM(E6+E7+E8+E9+E12) -> -18.144 | F16: =SUM(F6+F7+F8+F9+F12) -> 465.23912 | G16: =SUM(G6+G7+G8+G9+G12) -> 1522.9138 | H16: =SUM(H6+H7+H8+H9+H12) -> 1134.8307 | I16: =SUM(I6+I7+I8+I9+I12) -> 2381.9053 | ... U16: =SUM(U6+U7+U8+U9+U12) -> 4721.6451
A17: Unit Price | B17: =B16 -> -15.12 | C17: =C16/(1+(ScenarioParameters!$B$8/100)/4)^B3 -> -14.859951 | D17: =D16/(1+(ScenarioParameters!$B$8/100)/4)^C3 -> -14.604374 | E17: =E16/(1+(ScenarioParameters!$B$8/100)/4)^D3 -> -17.223832 | F17: =F16/(1+(ScenarioParameters!$B$8/100)/4)^E3 -> 434.0488 | G17: =G16/(1+(ScenarioParameters!$B$8/100)/4)^F3 -> 1396.3787 | H17: =H16/(1+(ScenarioParameters!$B$8/100)/4)^G3 -> 1022.6442 | I17: =I16/(1+(ScenarioParameters!$B$8/100)/4)^H3 -> 2109.5196 | J17: =J16/(1+(ScenarioParameters!$B$8/100)/4)^I3 -> 1055.7756 | ... U17: =U16/(1+(ScenarioParameters!$B$8/100)/4)^T3 -> 3395.7789
A19: Project NVP | B19: =SUM(B17:U17) -> 30394.601
A21: Forecasted Sales Volume from Winter's forecasting method*

Sheet +10% SalesVol
A1: Sales Volume Analysis: | B1: 0.1
B2: Year 0, Development | F2: Year 1, Projection | J2: Year 2, Projection | N2: Year 3, Projection | R2: Year 4, Projection
A3: Period | B3: 1 | C3: =B3+1 -> 2 | D3: =C3+1 -> 3 | E3: =D3+1 -> 4 | F3: =E3+1 -> 5 | G3: =F3+1 -> 6 | H3: =G3+1 -> 7 | I3: =H3+1 -> 8 | J3: =I3+1 -> 9 | ... U3: =T3+1 -> 20
A4: ($Value in thousands) | B4: Q1 | C4: Q2 | D4: Q3 | E4: Q4 | F4: Q1 | G4: Q2 | H4: Q3 | I4: Q4 | J4: Q1 | K4: Q2 | L4: Q3 | M4: Q4 | N4: Q1 | O4: Q2 | P4: Q3 | Q4: Q4 | R4: Q1 | S4: Q2 | T4: Q3 | U4: Q4
A6: Development Cost | B6: =(-1)*ScenarioParameters!$B$3/4*(1/1000) -> -15.12 | C6: =(-1)*ScenarioParameters!$B$3/4*(1/1000) -> -15.12 | D6: =(-1)*ScenarioParameters!$B$3/4*(1/1000) -> -15.12 | E6: =(-1)*ScenarioParameters!$B$3/4*(1/1000) -> -15.12
A7: Ramp-up cost | E7: =(-1)*ScenarioParameters!$B$6/2*(1/1000) -> -3.024 | F7: =(-1)*ScenarioParameters!$B$6/2*(1/1000) -> -3.024
A8: Marketing & support cost | F8: =(-1)*ScenarioParameters!$B$7/4*(1/1000) -> -210 | G8: =(-1)*ScenarioParameters!$B$7/4*(1/1000) -> -210 | H8: =(-1)*ScenarioParameters!$B$7/4*(1/1000) -> -210 | I8: =(-1)*ScenarioParameters!$B$7/4*(1/1000) -> -210 | J8: =(-1)*ScenarioParameters!$B$7/4*(1/1000) -> -210 | K8: =(-1)*ScenarioParameters!$B$7/4*(1/1000) -> -210 | L8: =(-1)*ScenarioParameters!$B$7/4*(1/1000) -> -210 | M8: =(-1)*ScenarioParameters!$B$7/4*(1/1000) -> -210 | ... U8: =(-1)*ScenarioParameters!$B$7/4*(1/1000) -> -210
A9: Production Cost | F9: =(-1)*(ScenarioParameters!$B$5)*ScenarioParameters!$G3*(1/1000) -> -358.17105 | G9: =(-1)*(ScenarioParameters!$B$5)*ScenarioParameters!$G4*(1/1000) -> -915.10143 | H9: =(-1)*(ScenarioParameters!$B$5)*ScenarioParameters!$G5*(1/1000) -> -710.166 | I9: =(-1)*(ScenarioParameters!$B$5)*ScenarioParameters!$G6*(1/1000) -> -1368.7099 | J9: =(-1)*(ScenarioParameters!$B$5)*ScenarioParameters!$G7*(1/1000) -> -751.42456 | K9: =(-1)*(ScenarioParameters!$B$5)*ScenarioParameters!$G8*(1/1000) -> -1496.0629 | L9: =(-1)*(ScenarioParameters!$B$5)*ScenarioParameters!$G9*(1/1000) -> -1010.0049 | M9: =(-1)*(ScenarioParameters!$B$5)*ScenarioParameters!$G10*(1/1000) -> -1796.7699 | N9: =(-1)*(ScenarioParameters!$B$5)*ScenarioParameters!$G11*(1/1000) -> -952.30836 | O9: =(-1)*(ScenarioParameters!$B$5)*ScenarioParameters!$G12*(1/1000) -> -1869.3415 | P9: =(-1)*(ScenarioParameters!$B$5)*ScenarioParameters!$G13*(1/1000) -> -1241.2506 | Q9: =(-1)*(ScenarioParameters!$B$5)*ScenarioParameters!$G14*(1/1000) -> -2183.9012 | R9: =(-1)*(ScenarioParameters!$B$5)*ScenarioParameters!$G15*(1/1000) -> -1166.5343 | S9: =(-1)*(ScenarioParameters!$B$5)*ScenarioParameters!$G16*(1/1000) -> -2267.4681 | T9: =(-1)*(ScenarioParameters!$B$5)*ScenarioParameters!$G17*(1/1000) -> -1492.2443 | U9: =(-1)*(ScenarioParameters!$B$5)*ScenarioParameters!$G18*(1/1000) -> -2604.2585
A10: Production volume | F10: =ScenarioParameters!$G3+ScenarioParameters!$G3*$B$1 -> 3417.6627 | G10: =ScenarioParameters!$G4+ScenarioParameters!$G4*$B$1 -> 8731.8839 | H10: =ScenarioParameters!$G5+ScenarioParameters!$G5*$B$1 -> 6776.3931 | I10: =ScenarioParameters!$G6+ScenarioParameters!$G6*$B$1 -> 13060.209 | J10: =ScenarioParameters!$G7+ScenarioParameters!$G7*$B$1 -> 7170.0817 | K10: =ScenarioParameters!$G8+ScenarioParameters!$G8*$B$1 -> 14275.41 | L10: =ScenarioParameters!$G9+ScenarioParameters!$G9*$B$1 -> 9637.4517 | M10: =ScenarioParameters!$G10+ScenarioParameters!$G10*$B$1 -> 17144.751 | N10: =ScenarioParameters!$G11+ScenarioParameters!$G11*$B$1 -> 9086.9118 | O10: =ScenarioParameters!$G12+ScenarioParameters!$G12*$B$1 -> 17837.228 | P10: =ScenarioParameters!$G13+ScenarioParameters!$G13*$B$1 -> 11843.994 | Q10: =ScenarioParameters!$G14+ScenarioParameters!$G14*$B$1 -> 20838.752 | R10: =ScenarioParameters!$G15+ScenarioParameters!$G15*$B$1 -> 11131.053 | S10: =ScenarioParameters!$G16+ScenarioParameters!$G16*$B$1 -> 21636.146 | T10: =ScenarioParameters!$G17+ScenarioParameters!$G17*$B$1 -> 14238.972 | U10: =ScenarioParameters!$G18+ScenarioParameters!$G18*$B$1 -> 24849.795
A11: Unit product cost | F11: =F9/F10 -> -0.1048 | G11: =G9/G10 -> -0.1048 | H11: =H9/H10 -> -0.1048 | I11: =I9/I10 -> -0.1048 | J11: =J9/J10 -> -0.1048 | K11: =K9/K10 -> -0.1048 | L11: =L9/L10 -> -0.1048 | M11: =M9/M10 -> -0.1048 | ... U11: =U9/U10 -> -0.1048
A12: Sales revenue | F12: =(ScenarioParameters!$B$4*F10)*(1/1000) -> 1021.8811 | G12: =(ScenarioParameters!$B$4*G10)*(1/1000) -> 2610.8333 | H12: =(ScenarioParameters!$B$4*H10)*(1/1000) -> 2026.1415 | I12: =(ScenarioParameters!$B$4*I10)*(1/1000) -> 3905.0024 | J12: =(ScenarioParameters!$B$4*J10)*(1/1000) -> 2143.8544 | K12: =(ScenarioParameters!$B$4*K10)*(1/1000) -> 4268.3475 | L12: =(ScenarioParameters!$B$4*L10)*(1/1000) -> 2881.5981 | M12: =(ScenarioParameters!$B$4*M10)*(1/1000) -> 5126.2805 | ... U12: =(ScenarioParameters!$B$4*U10)*(1/1000) -> 7430.0886
A13: Forecasted Sales Volume | F13: =F$10 -> 3417.6627 | G13: =G$10 -> 8731.8839 | H13: =H$10 -> 6776.3931 | I13: =I$10 -> 13060.209 | J13: =J$10 -> 7170.0817 | K13: =K$10 -> 14275.41 | L13: =L$10 -> 9637.4517 | M13: =M$10 -> 17144.751 | ... U13: =U$10 -> 24849.795
A14: Unit price | F14: =F$12/F$13 -> 0.299 | G14: =G$12/G$13 -> 0.299 | H14: =H$12/H$13 -> 0.299 | I14: =I$12/I$13 -> 0.299 | J14: =J$12/J$13 -> 0.299 | K14: =K$12/K$13 -> 0.299 | L14: =L$12/L$13 -> 0.299 | M14: =M$12/M$13 -> 0.299 | ... U14: =U$12/U$13 -> 0.299
A16: Period Cash Flow | B16: =SUM(B6+B7+B8+B9+B12) -> -15.12 | C16: =SUM(C6+C7+C8+C9+C12) -> -15.12 | D16: =SUM(D6+D7+D8+D9+D12) -> -15.12 | E16: =SUM(E6+E7+E8+E9+E12) -> -18.144 | F16: =SUM(F6+F7+F8+F9+F12) -> 450.68609 | G16: =SUM(G6+G7+G8+G9+G12) -> 1485.7318 | H16: =SUM(H6+H7+H8+H9+H12) -> 1105.9755 | I16: =SUM(I6+I7+I8+I9+I12) -> 2326.2925 | ... U16: =SUM(U6+U7+U8+U9+U12) -> 4615.8302
A17: Unit Price | B17: =B16 -> -15.12 | C17: =C16/(1+(ScenarioParameters!$B$8/100)/4)^B3 -> -14.859951 | D17: =D16/(1+(ScenarioParameters!$B$8/100)/4)^C3 -> -14.604374 | E17: =E16/(1+(ScenarioParameters!$B$8/100)/4)^D3 -> -17.223832 | F17: =F16/(1+(ScenarioParameters!$B$8/100)/4)^E3 -> 420.47142 | G17: =G16/(1+(ScenarioParameters!$B$8/100)/4)^F3 -> 1362.2862 | H17: =H16/(1+(ScenarioParameters!$B$8/100)/4)^G3 -> 996.64161 | I17: =I16/(1+(ScenarioParameters!$B$8/100)/4)^H3 -> 2060.2665 | J17: =J16/(1+(ScenarioParameters!$B$8/100)/4)^I3 -> 1029.2006 | ... U17: =U16/(1+(ScenarioParameters!$B$8/100)/4)^T3 -> 3319.6774
A19: Project NVP | B19: =SUM(B17:U17) -> 30070.4
A21: Forecasted Sales Volume from Winter's forecasting method*

Sheet -10% SalesVol
A1: Sales Volume Analysis: | B1: -0.1
B2: Year 0, Development | F2: Year 1, Projection | J2: Year 2, Projection | N2: Year 3, Projection | R2: Year 4, Projection
A3: Period | B3: 1 | C3: =B3+1 -> 2 | D3: =C3+1 -> 3 | E3: =D3+1 -> 4 | F3: =E3+1 -> 5 | G3: =F3+1 -> 6 | H3: =G3+1 -> 7 | I3: =H3+1 -> 8 | J3: =I3+1 -> 9 | ... U3: =T3+1 -> 20
A4: ($Value in thousands) | B4: Q1 | C4: Q2 | D4: Q3 | E4: Q4 | F4: Q1 | G4: Q2 | H4: Q3 | I4: Q4 | J4: Q1 | K4: Q2 | L4: Q3 | M4: Q4 | N4: Q1 | O4: Q2 | P4: Q3 | Q4: Q4 | R4: Q1 | S4: Q2 | T4: Q3 | U4: Q4
A6: Development Cost | B6: =(-1)*ScenarioParameters!$B$3/4*(1/1000) -> -15.12 | C6: =(-1)*ScenarioParameters!$B$3/4*(1/1000) -> -15.12 | D6: =(-1)*ScenarioParameters!$B$3/4*(1/1000) -> -15.12 | E6: =(-1)*ScenarioParameters!$B$3/4*(1/1000) -> -15.12
A7: Ramp-up cost | E7: =(-1)*ScenarioParameters!$B$6/2*(1/1000) -> -3.024 | F7: =(-1)*ScenarioParameters!$B$6/2*(1/1000) -> -3.024
A8: Marketing & support cost | F8: =(-1)*ScenarioParameters!$B$7/4*(1/1000) -> -210 | G8: =(-1)*ScenarioParameters!$B$7/4*(1/1000) -> -210 | H8: =(-1)*ScenarioParameters!$B$7/4*(1/1000) -> -210 | I8: =(-1)*ScenarioParameters!$B$7/4*(1/1000) -> -210 | J8: =(-1)*ScenarioParameters!$B$7/4*(1/1000) -> -210 | K8: =(-1)*ScenarioParameters!$B$7/4*(1/1000) -> -210 | L8: =(-1)*ScenarioParameters!$B$7/4*(1/1000) -> -210 | M8: =(-1)*ScenarioParameters!$B$7/4*(1/1000) -> -210 | ... U8: =(-1)*ScenarioParameters!$B$7/4*(1/1000) -> -210
A9: Production Cost | F9: =(-1)*(ScenarioParameters!$B$5)*ScenarioParameters!$G3*(1/1000) -> -358.17105 | G9: =(-1)*(ScenarioParameters!$B$5)*ScenarioParameters!$G4*(1/1000) -> -915.10143 | H9: =(-1)*(ScenarioParameters!$B$5)*ScenarioParameters!$G5*(1/1000) -> -710.166 | I9: =(-1)*(ScenarioParameters!$B$5)*ScenarioParameters!$G6*(1/1000) -> -1368.7099 | J9: =(-1)*(ScenarioParameters!$B$5)*ScenarioParameters!$G7*(1/1000) -> -751.42456 | K9: =(-1)*(ScenarioParameters!$B$5)*ScenarioParameters!$G8*(1/1000) -> -1496.0629 | L9: =(-1)*(ScenarioParameters!$B$5)*ScenarioParameters!$G9*(1/1000) -> -1010.0049 | M9: =(-1)*(ScenarioParameters!$B$5)*ScenarioParameters!$G10*(1/1000) -> -1796.7699 | N9: =(-1)*(ScenarioParameters!$B$5)*ScenarioParameters!$G11*(1/1000) -> -952.30836 | O9: =(-1)*(ScenarioParameters!$B$5)*ScenarioParameters!$G12*(1/1000) -> -1869.3415 | P9: =(-1)*(ScenarioParameters!$B$5)*ScenarioParameters!$G13*(1/1000) -> -1241.2506 | Q9: =(-1)*(ScenarioParameters!$B$5)*ScenarioParameters!$G14*(1/1000) -> -2183.9012 | R9: =(-1)*(ScenarioParameters!$B$5)*ScenarioParameters!$G15*(1/1000) -> -1166.5343 | S9: =(-1)*(ScenarioParameters!$B$5)*ScenarioParameters!$G16*(1/1000) -> -2267.4681 | T9: =(-1)*(ScenarioParameters!$B$5)*ScenarioParameters!$G17*(1/1000) -> -1492.2443 | U9: =(-1)*(ScenarioParameters!$B$5)*ScenarioParameters!$G18*(1/1000) -> -2604.2585
A10: Production volume | F10: =ScenarioParameters!$G3+ScenarioParameters!$G3*$B$1 -> 2796.2695 | G10: =ScenarioParameters!$G4+ScenarioParameters!$G4*$B$1 -> 7144.2686 | H10: =ScenarioParameters!$G5+ScenarioParameters!$G5*$B$1 -> 5544.3216 | I10: =ScenarioParameters!$G6+ScenarioParameters!$G6*$B$1 -> 10685.625 | J10: =ScenarioParameters!$G7+ScenarioParameters!$G7*$B$1 -> 5866.4305 | K10: =ScenarioParameters!$G8+ScenarioParameters!$G8*$B$1 -> 11679.881 | L10: =ScenarioParameters!$G9+ScenarioParameters!$G9*$B$1 -> 7885.1878 | M10: =ScenarioParameters!$G10+ScenarioParameters!$G10*$B$1 -> 14027.523 | N10: =ScenarioParameters!$G11+ScenarioParameters!$G11*$B$1 -> 7434.746 | O10: =ScenarioParameters!$G12+ScenarioParameters!$G12*$B$1 -> 14594.096 | P10: =ScenarioParameters!$G13+ScenarioParameters!$G13*$B$1 -> 9690.5405 | Q10: =ScenarioParameters!$G14+ScenarioParameters!$G14*$B$1 -> 17049.888 | R10: =ScenarioParameters!$G15+ScenarioParameters!$G15*$B$1 -> 9107.225 | S10: =ScenarioParameters!$G16+ScenarioParameters!$G16*$B$1 -> 17702.301 | T10: =ScenarioParameters!$G17+ScenarioParameters!$G17*$B$1 -> 11650.068 | U10: =ScenarioParameters!$G18+ScenarioParameters!$G18*$B$1 -> 20331.65
A11: Unit product cost | F11: =F9/F10 -> -0.12808889 | G11: =G9/G10 -> -0.12808889 | H11: =H9/H10 -> -0.12808889 | I11: =I9/I10 -> -0.12808889 | J11: =J9/J10 -> -0.12808889 | K11: =K9/K10 -> -0.12808889 | L11: =L9/L10 -> -0.12808889 | M11: =M9/M10 -> -0.12808889 | ... U11: =U9/U10 -> -0.12808889
A12: Sales revenue | F12: =(ScenarioParameters!$B$4*F10)*(1/1000) -> 836.08457 | G12: =(ScenarioParameters!$B$4*G10)*(1/1000) -> 2136.1363 | H12: =(ScenarioParameters!$B$4*H10)*(1/1000) -> 1657.7522 | I12: =(ScenarioParameters!$B$4*I10)*(1/1000) -> 3195.002 | J12: =(ScenarioParameters!$B$4*J10)*(1/1000) -> 1754.0627 | K12: =(ScenarioParameters!$B$4*K10)*(1/1000) -> 3492.2843 | L12: =(ScenarioParameters!$B$4*L10)*(1/1000) -> 2357.6711 | M12: =(ScenarioParameters!$B$4*M10)*(1/1000) -> 4194.2295 | ... U12: =(ScenarioParameters!$B$4*U10)*(1/1000) -> 6079.1634
A13: Forecasted Sales Volume | F13: =F$10 -> 2796.2695 | G13: =G$10 -> 7144.2686 | H13: =H$10 -> 5544.3216 | I13: =I$10 -> 10685.625 | J13: =J$10 -> 5866.4305 | K13: =K$10 -> 11679.881 | L13: =L$10 -> 7885.1878 | M13: =M$10 -> 14027.523 | ... U13: =U$10 -> 20331.65
